Workbook

Sheet Amazon Weekly Sales Rpt 
A1: IDENTIFYING INFO | AL1: On Order Info | AM1: On Order Info
A2: Dealer Name | B2: Month Ending | D2: UPC | E2: FBM Specific Combo | F2: FBA Specific Combo | G2: ASIN | H2: FBM Only vs FBA Designations | I2: Style # | J2: Description | K2: Color | L2: Size | M2: GoBros List Price | N2: FBA List Price | O2: GoBros COG (Includes Earned 10% Discount) | P2: Lowest Price on AMZ Difference | R2: GB Units Sold | S2: GB $$ Volume | U2: FBM Units Sold | V2: FBM $$ Volume | W2: Sessions | X2: Featured Offer (Buy Box) Percentage | Z2: FBA Units Sold | AA2: FBA $$ Volume | AB2: Sessions | AC2: Featured Offer (Buy Box) Percentage | AE2: Fulfillable Units FBM | AF2: Fulfillable FBA | AG2: Inbound FBA | AH2: Processing FBA | AI2: TOTAL at FBA | AJ2: TOTAL BY UNITS (FBM and FBA) | AK2: Current Holdings Inventory Value | AL2: FBA 5.14ZZ, Backorders, Listing Issues | AM2: GB/FBM (12.9 GB and Backorders)
A3: GoBros | B3: 46173 | D3: 048323011686 | E3: WIGF1019_051_wht_0 | F3: ZZWIGF1019_051_wht_0M | G3: #N/A | H3: FBM Only | I3: F1019 | J3: Wigwam 7-Footer Extra Tall Socks | K3: White | L3: One Size Fits Most | O3: 6.48 | R3: =IFERROR(VLOOKUP(E3,Sheet6!$A$2:$B$500,2,FALSE),0) -> 7 | S3: =IFERROR(VLOOKUP(E3,Sheet6!$C$2:$D$35017,2,FALSE),0) -> 105 | U3: =IFERROR(VLOOKUP(E3,Sheet2!$AA$1:$AB$975,2,FALSE),0) -> 5 | V3: =IFERROR(VLOOKUP(E3,Sheet2!$AC$1:$AD$975,2,FALSE),0) -> 74.95 | W3: =IFERROR(VLOOKUP(E3,Sheet2!$AE$1:$AF$975,2,FALSE),0) -> 86 | X3: =IFERROR(VLOOKUP(E3,Sheet2!$AG$1:$AH$975,2,FALSE),0) -> 0.1339 | Z3: =IFERROR(VLOOKUP(F3,Sheet2!$AA$1:$AB$975,2,FALSE),0) -> 0 | AA3: =IFERROR(VLOOKUP(F3,Sheet2!$AC$1:$AD$975,2,FALSE),0) -> 0 | AB3: =IFERROR(VLOOKUP(F3,Sheet2!$AE$2:$AF$6539,2,FALSE),0) -> 0 | AC3: =IFERROR(VLOOKUP(F3,Sheet2!$AG$2:$AH$6539,2,FALSE),0) -> 0 | AE3: 188 | AF3: 0 | AG3: 0 | AH3: 0 | AI3: 0 | AJ3: =SUM(AE3+AI3) -> 188 | AK3: =SUM(AJ3*O3) -> 1218.24 | AL3: 0 | AM3: 0
A4: GoBros | B4: 46173 | D4: 048323013185 | E4: WIGF1054_051_whi_1 | F4: ZZWIGF1054_051_whi_1 | G4: #N/A | H4: FBM Only | I4: F1054 | J4: Wigwam Volley Midweight Crew Socks | K4: White | L4: Medium | O4: 5.85 | R4: =IFERROR(VLOOKUP(E4,Sheet6!$A$2:$B$500,2,FALSE),0) -> 0 | S4: =IFERROR(VLOOKUP(E4,Sheet6!$C$2:$D$35017,2,FALSE),0) -> 0 | U4: =IFERROR(VLOOKUP(E4,Sheet2!$AA$1:$AB$975,2,FALSE),0) -> 5 | V4: =IFERROR(VLOOKUP(E4,Sheet2!$AC$1:$AD$975,2,FALSE),0) -> 65 | W4: =IFERROR(VLOOKUP(E4,Sheet2!$AE$1:$AF$975,2,FALSE),0) -> 7 | X4: =IFERROR(VLOOKUP(E4,Sheet2!$AG$1:$AH$975,2,FALSE),0) -> 1 | Z4: =IFERROR(VLOOKUP(F4,Sheet2!$AA$1:$AB$975,2,FALSE),0) -> 0 | AA4: =IFERROR(VLOOKUP(F4,Sheet2!$AC$1:$AD$975,2,FALSE),0) -> 0 | AB4: =IFERROR(VLOOKUP(F4,Sheet2!$AE$2:$AF$6539,2,FALSE),0) -> 0 | AC4: =IFERROR(VLOOKUP(F4,Sheet2!$AG$2:$AH$6539,2,FALSE),0) -> 0 | AE4: 3 | AF4: 0 | AG4: 0 | AH4: 0 | AI4: 0 | AJ4: =SUM(AE4+AI4) -> 3 | AK4: =SUM(AJ4*O4) -> 17.55 | AL4: 0 | AM4: 0
A5: GoBros | B5: 46173 | D5: 048323013178 | E5: WIGF1054_051_whi_2 | F5: ZZWIGF1054_051_whi_2 | G5: #N/A | H5: FBM Only | I5: F1054 | J5: Wigwam Volley Midweight Crew Socks | K5: White | L5: Large | O5: 5.85 | R5: =IFERROR(VLOOKUP(E5,Sheet6!$A$2:$B$500,2,FALSE),0) -> 0 | S5: =IFERROR(VLOOKUP(E5,Sheet6!$C$2:$D$35017,2,FALSE),0) -> 0 | U5: =IFERROR(VLOOKUP(E5,Sheet2!$AA$1:$AB$975,2,FALSE),0) -> 0 | V5: =IFERROR(VLOOKUP(E5,Sheet2!$AC$1:$AD$975,2,FALSE),0) -> 0 | W5: =IFERROR(VLOOKUP(E5,Sheet2!$AE$1:$AF$975,2,FALSE),0) -> 0 | X5: =IFERROR(VLOOKUP(E5,Sheet2!$AG$1:$AH$975,2,FALSE),0) -> 0 | Z5: =IFERROR(VLOOKUP(F5,Sheet2!$AA$1:$AB$975,2,FALSE),0) -> 0 | AA5: =IFERROR(VLOOKUP(F5,Sheet2!$AC$1:$AD$975,2,FALSE),0) -> 0 | AB5: =IFERROR(VLOOKUP(F5,Sheet2!$AE$2:$AF$6539,2,FALSE),0) -> 0 | AC5: =IFERROR(VLOOKUP(F5,Sheet2!$AG$2:$AH$6539,2,FALSE),0) -> 0 | AE5: 3 | AF5: 0 | AG5: 0 | AH5: 0 | AI5: 0 | AJ5: =SUM(AE5+AI5) -> 3 | AK5: =SUM(AJ5*O5) -> 17.55 | AL5: 0 | AM5: 0
A6: GoBros | B6: 46173 | D6: 048323013192 | E6: WIGF1054_051_whi_3 | F6: ZZWIGF1054_051_whi_3 | G6: #N/A | H6: FBM Only | I6: F1054 | J6: Wigwam Volley Midweight Crew Socks | K6: White | L6: X-Large | O6: 5.85 | R6: =IFERROR(VLOOKUP(E6,Sheet6!$A$2:$B$500,2,FALSE),0) -> 0 | S6: =IFERROR(VLOOKUP(E6,Sheet6!$C$2:$D$35017,2,FALSE),0) -> 0 | U6: =IFERROR(VLOOKUP(E6,Sheet2!$AA$1:$AB$975,2,FALSE),0) -> 0 | V6: =IFERROR(VLOOKUP(E6,Sheet2!$AC$1:$AD$975,2,FALSE),0) -> 0 | W6: =IFERROR(VLOOKUP(E6,Sheet2!$AE$1:$AF$975,2,FALSE),0) -> 0 | X6: =IFERROR(VLOOKUP(E6,Sheet2!$AG$1:$AH$975,2,FALSE),0) -> 0 | Z6: =IFERROR(VLOOKUP(F6,Sheet2!$AA$1:$AB$975,2,FALSE),0) -> 0 | AA6: =IFERROR(VLOOKUP(F6,Sheet2!$AC$1:$AD$975,2,FALSE),0) -> 0 | AB6: =IFERROR(VLOOKUP(F6,Sheet2!$AE$2:$AF$6539,2,FALSE),0) -> 0 | AC6: =IFERROR(VLOOKUP(F6,Sheet2!$AG$2:$AH$6539,2,FALSE),0) -> 0 | AE6: 26 | AF6: 0 | AG6: 0 | AH6: 0 | AI6: 0 | AJ6: =SUM(AE6+AI6) -> 26 | AK6: =SUM(AJ6*O6) -> 152.1 | AL6: 0 | AM6: 0
A7: GoBros | B7: 46173 | D7: 048323013208 | E7: WIGF1054_051_whi_4 | F7: ZZWIGF1054_051_whi_4 | G7: #N/A | H7: FBM Only | I7: F1054 | J7: Wigwam Volley Midweight Crew Socks | K7: White | L7: XX-Large | O7: 5.85 | R7: =IFERROR(VLOOKUP(E7,Sheet6!$A$2:$B$500,2,FALSE),0) -> 0 | S7: =IFERROR(VLOOKUP(E7,Sheet6!$C$2:$D$35017,2,FALSE),0) -> 0 | U7: =IFERROR(VLOOKUP(E7,Sheet2!$AA$1:$AB$975,2,FALSE),0) -> 0 | V7: =IFERROR(VLOOKUP(E7,Sheet2!$AC$1:$AD$975,2,FALSE),0) -> 0 | W7: =IFERROR(VLOOKUP(E7,Sheet2!$AE$1:$AF$975,2,FALSE),0) -> 0 | X7: =IFERROR(VLOOKUP(E7,Sheet2!$AG$1:$AH$975,2,FALSE),0) -> 0 | Z7: =IFERROR(VLOOKUP(F7,Sheet2!$AA$1:$AB$975,2,FALSE),0) -> 0 | AA7: =IFERROR(VLOOKUP(F7,Sheet2!$AC$1:$AD$975,2,FALSE),0) -> 0 | AB7: =IFERROR(VLOOKUP(F7,Sheet2!$AE$2:$AF$6539,2,FALSE),0) -> 0 | AC7: =IFERROR(VLOOKUP(F7,Sheet2!$AG$2:$AH$6539,2,FALSE),0) -> 0 | AE7: 13 | AF7: 0 | AG7: 0 | AH7: 0 | AI7: 0 | AJ7: =SUM(AE7+AI7) -> 13 | AK7: =SUM(AJ7*O7) -> 76.05 | AL7: 0 | AM7: 0
A8: GoBros | B8: 46173 | D8: 048323434096 | E8: WIGF1054_052_bla_1 | F8: ZZWIGF1054_052_bla_1 | G8: #N/A | H8: FBM Only | I8: F1054 | J8: Wigwam Volley Midweight Crew Socks | K8: Black | L8: Medium | O8: 5.85 | R8: =IFERROR(VLOOKUP(E8,Sheet6!$A$2:$B$500,2,FALSE),0) -> 0 | S8: =IFERROR(VLOOKUP(E8,Sheet6!$C$2:$D$35017,2,FALSE),0) -> 0 | U8: =IFERROR(VLOOKUP(E8,Sheet2!$AA$1:$AB$975,2,FALSE),0) -> 0 | V8: =IFERROR(VLOOKUP(E8,Sheet2!$AC$1:$AD$975,2,FALSE),0) -> 0 | W8: =IFERROR(VLOOKUP(E8,Sheet2!$AE$1:$AF$975,2,FALSE),0) -> 0 | X8: =IFERROR(VLOOKUP(E8,Sheet2!$AG$1:$AH$975,2,FALSE),0) -> 0 | Z8: =IFERROR(VLOOKUP(F8,Sheet2!$AA$1:$AB$975,2,FALSE),0) -> 0 | AA8: =IFERROR(VLOOKUP(F8,Sheet2!$AC$1:$AD$975,2,FALSE),0) -> 0 | AB8: =IFERROR(VLOOKUP(F8,Sheet2!$AE$2:$AF$6539,2,FALSE),0) -> 0 | AC8: =IFERROR(VLOOKUP(F8,Sheet2!$AG$2:$AH$6539,2,FALSE),0) -> 0 | AE8: 0 | AF8: 0 | AG8: 0 | AH8: 0 | AI8: 0 | AJ8: =SUM(AE8+AI8) -> 0 | AK8: =SUM(AJ8*O8) -> 0 | AL8: 0 | AM8: 0
A9: GoBros | B9: 46173 | D9: 048323434102 | E9: WIGF1054_052_bla_2 | F9: ZZWIGF1054_052_bla_2 | G9: #N/A | H9: FBM Only | I9: F1054 | J9: Wigwam Volley Midweight Crew Socks | K9: Black | L9: Large | O9: 5.85 | R9: =IFERROR(VLOOKUP(E9,Sheet6!$A$2:$B$500,2,FALSE),0) -> 0 | S9: =IFERROR(VLOOKUP(E9,Sheet6!$C$2:$D$35017,2,FALSE),0) -> 0 | U9: =IFERROR(VLOOKUP(E9,Sheet2!$AA$1:$AB$975,2,FALSE),0) -> 3 | V9: =IFERROR(VLOOKUP(E9,Sheet2!$AC$1:$AD$975,2,FALSE),0) -> 39 | W9: =IFERROR(VLOOKUP(E9,Sheet2!$AE$1:$AF$975,2,FALSE),0) -> 11 | X9: =IFERROR(VLOOKUP(E9,Sheet2!$AG$1:$AH$975,2,FALSE),0) -> 1 | Z9: =IFERROR(VLOOKUP(F9,Sheet2!$AA$1:$AB$975,2,FALSE),0) -> 0 | AA9: =IFERROR(VLOOKUP(F9,Sheet2!$AC$1:$AD$975,2,FALSE),0) -> 0 | AB9: =IFERROR(VLOOKUP(F9,Sheet2!$AE$2:$AF$6539,2,FALSE),0) -> 0 | AC9: =IFERROR(VLOOKUP(F9,Sheet2!$AG$2:$AH$6539,2,FALSE),0) -> 0 | AE9: 6 | AF9: 0 | AG9: 0 | AH9: 0 | AI9: 0 | AJ9: =SUM(AE9+AI9) -> 6 | AK9: =SUM(AJ9*O9) -> 35.1 | AL9: 0 | AM9: 0
A10: GoBros | B10: 46173 | D10: 048323434119 | E10: WIGF1054_052_bla_3 | F10: ZZWIGF1054_052_bla_3 | G10: #N/A | H10: FBM Only | I10: F1054 | J10: Wigwam Volley Midweight Crew Socks | K10: Black | L10: X-Large | O10: 5.85 | R10: =IFERROR(VLOOKUP(E10,Sheet6!$A$2:$B$500,2,FALSE),0) -> 3 | S10: =IFERROR(VLOOKUP(E10,Sheet6!$C$2:$D$35017,2,FALSE),0) -> 39 | U10: =IFERROR(VLOOKUP(E10,Sheet2!$AA$1:$AB$975,2,FALSE),0) -> 1 | V10: =IFERROR(VLOOKUP(E10,Sheet2!$AC$1:$AD$975,2,FALSE),0) -> 13 | W10: =IFERROR(VLOOKUP(E10,Sheet2!$AE$1:$AF$975,2,FALSE),0) -> 2 | X10: =IFERROR(VLOOKUP(E10,Sheet2!$AG$1:$AH$975,2,FALSE),0) -> 1 | Z10: =IFERROR(VLOOKUP(F10,Sheet2!$AA$1:$AB$975,2,FALSE),0) -> 0 | AA10: =IFERROR(VLOOKUP(F10,Sheet2!$AC$1:$AD$975,2,FALSE),0) -> 0 | AB10: =IFERROR(VLOOKUP(F10,Sheet2!$AE$2:$AF$6539,2,FALSE),0) -> 0 | AC10: =IFERROR(VLOOKUP(F10,Sheet2!$AG$2:$AH$6539,2,FALSE),0) -> 0 | AE10: 7 | AF10: 0 | AG10: 0 | AH10: 0 | AI10: 0 | AJ10: =SUM(AE10+AI10) -> 7 | AK10: =SUM(AJ10*O10) -> 40.95 | AL10: 0 | AM10: 0
A11: GoBros | B11: 46173 | D11: 048323013437 | E11: WIGF1055_051_wht_0 | F11: ZZWIGF1055_051_wht_0 | G11: #N/A | H11: FBM Only | I11: F1055 | J11: Wigwam King Cotton Heavyweight Crew Socks | K11: White | L11: Medium | O11: 6.48 | R11: =IFERROR(VLOOKUP(E11,Sheet6!$A$2:$B$500,2,FALSE),0) -> 0 | S11: =IFERROR(VLOOKUP(E11,Sheet6!$C$2:$D$35017,2,FALSE),0) -> 0 | U11: =IFERROR(VLOOKUP(E11,Sheet2!$AA$1:$AB$975,2,FALSE),0) -> 0 | V11: =IFERROR(VLOOKUP(E11,Sheet2!$AC$1:$AD$975,2,FALSE),0) -> 0 | W11: =IFERROR(VLOOKUP(E11,Sheet2!$AE$1:$AF$975,2,FALSE),0) -> 0 | X11: =IFERROR(VLOOKUP(E11,Sheet2!$AG$1:$AH$975,2,FALSE),0) -> 0 | Z11: =IFERROR(VLOOKUP(F11,Sheet2!$AA$1:$AB$975,2,FALSE),0) -> 0 | AA11: =IFERROR(VLOOKUP(F11,Sheet2!$AC$1:$AD$975,2,FALSE),0) -> 0 | AB11: =IFERROR(VLOOKUP(F11,Sheet2!$AE$2:$AF$6539,2,FALSE),0) -> 0 | AC11: =IFERROR(VLOOKUP(F11,Sheet2!$AG$2:$AH$6539,2,FALSE),0) -> 0 | AE11: 0 | AF11: 0 | AG11: 0 | AH11: 0 | AI11: 0 | AJ11: =SUM(AE11+AI11) -> 0 | AK11: =SUM(AJ11*O11) -> 0 | AL11: 0 | AM11: 0
A12: GoBros | B12: 46173 | D12: 048323013420 | E12: WIGF1055_051_wht_1 | F12: ZZWIGF1055_051_wht_1 | G12: #N/A | H12: FBM Only | I12: F1055 | J12: Wigwam King Cotton Heavyweight Crew Socks | K12: White | L12: Large | O12: 6.48 | R12: =IFERROR(VLOOKUP(E12,Sheet6!$A$2:$B$500,2,FALSE),0) -> 12 | S12: =IFERROR(VLOOKUP(E12,Sheet6!$C$2:$D$35017,2,FALSE),0) -> 180 | U12: =IFERROR(VLOOKUP(E12,Sheet2!$AA$1:$AB$975,2,FALSE),0) -> 87 | V12: =IFERROR(VLOOKUP(E12,Sheet2!$AC$1:$AD$975,2,FALSE),0) -> 1304.13 | W12: =IFERROR(VLOOKUP(E12,Sheet2!$AE$1:$AF$975,2,FALSE),0) -> 271 | X12: =IFERROR(VLOOKUP(E12,Sheet2!$AG$1:$AH$975,2,FALSE),0) -> 1 | Z12: =IFERROR(VLOOKUP(F12,Sheet2!$AA$1:$AB$975,2,FALSE),0) -> 0 | AA12: =IFERROR(VLOOKUP(F12,Sheet2!$AC$1:$AD$975,2,FALSE),0) -> 0 | AB12: =IFERROR(VLOOKUP(F12,Sheet2!$AE$2:$AF$6539,2,FALSE),0) -> 0 | AC12: =IFERROR(VLOOKUP(F12,Sheet2!$AG$2:$AH$6539,2,FALSE),0) -> 0 | AE12: 68 | AF12: 0 | AG12: 0 | AH12: 0 | AI12: 0 | AJ12: =SUM(AE12+AI12) -> 68 | AK12: =SUM(AJ12*O12) -> 440.64 | AL12: 0 | AM12: 12
A13: GoBros | B13: 46173 | D13: 048323013444 | E13: WIGF1055_051_wht_2 | F13: ZZWIGF1055_051_wht_2 | G13: #N/A | H13: FBM Only | I13: F1055 | J13: Wigwam King Cotton Heavyweight Crew Socks | K13: White | L13: X-Large | O13: 6.48 | R13: =IFERROR(VLOOKUP(E13,Sheet6!$A$2:$B$500,2,FALSE),0) -> 8 | S13: =IFERROR(VLOOKUP(E13,Sheet6!$C$2:$D$35017,2,FALSE),0) -> 117.75 | U13: =IFERROR(VLOOKUP(E13,Sheet2!$AA$1:$AB$975,2,FALSE),0) -> 46 | V13: =IFERROR(VLOOKUP(E13,Sheet2!$AC$1:$AD$975,2,FALSE),0) -> 690 | W13: =IFERROR(VLOOKUP(E13,Sheet2!$AE$1:$AF$975,2,FALSE),0) -> 131 | X13: =IFERROR(VLOOKUP(E13,Sheet2!$AG$1:$AH$975,2,FALSE),0) -> 1 | Z13: =IFERROR(VLOOKUP(F13,Sheet2!$AA$1:$AB$975,2,FALSE),0) -> 0 | AA13: =IFERROR(VLOOKUP(F13,Sheet2!$AC$1:$AD$975,2,FALSE),0) -> 0 | AB13: =IFERROR(VLOOKUP(F13,Sheet2!$AE$2:$AF$6539,2,FALSE),0) -> 0 | AC13: =IFERROR(VLOOKUP(F13,Sheet2!$AG$2:$AH$6539,2,FALSE),0) -> 0 | AE13: 251 | AF13: 0 | AG13: 0 | AH13: 0 | AI13: 0 | AJ13: =SUM(AE13+AI13) -> 251 | AK13: =SUM(AJ13*O13) -> 1626.48 | AL13: 0 | AM13: 0
A14: GoBros | B14: 46173 | D14: 048323485180 | E14: WIGF1055_052_blk_0 | F14: ZZWIGF1055_052_blk_0 | G14: #N/A | H14: FBM Only | I14: F1055 | J14: Wigwam King Cotton Heavyweight Crew Socks | K14: Black | L14: Medium | O14: 6.48 | R14: =IFERROR(VLOOKUP(E14,Sheet6!$A$2:$B$500,2,FALSE),0) -> 0 | S14: =IFERROR(VLOOKUP(E14,Sheet6!$C$2:$D$35017,2,FALSE),0) -> 0 | U14: =IFERROR(VLOOKUP(E14,Sheet2!$AA$1:$AB$975,2,FALSE),0) -> 0 | V14: =IFERROR(VLOOKUP(E14,Sheet2!$AC$1:$AD$975,2,FALSE),0) -> 0 | W14: =IFERROR(VLOOKUP(E14,Sheet2!$AE$1:$AF$975,2,FALSE),0) -> 0 | X14: =IFERROR(VLOOKUP(E14,Sheet2!$AG$1:$AH$975,2,FALSE),0) -> 0 | Z14: =IFERROR(VLOOKUP(F14,Sheet2!$AA$1:$AB$975,2,FALSE),0) -> 0 | AA14: =IFERROR(VLOOKUP(F14,Sheet2!$AC$1:$AD$975,2,FALSE),0) -> 0 | AB14: =IFERROR(VLOOKUP(F14,Sheet2!$AE$2:$AF$6539,2,FALSE),0) -> 0 | AC14: =IFERROR(VLOOKUP(F14,Sheet2!$AG$2:$AH$6539,2,FALSE),0) -> 0 | AE14: 28 | AF14: 0 | AG14: 0 | AH14: 0 | AI14: 0 | AJ14: =SUM(AE14+AI14) -> 28 | AK14: =SUM(AJ14*O14) -> 181.44 | AL14: 0 | AM14: 0
... A22: GoBros | B22: 46173 | D22: 048323013697 | E22: WIGF1057_51_whi_3 | F22: ZZWIGF1057_51_whi_3 | G22: #N/A | H22: FBM Only | I22: F1057 | J22: Wigwam King Cotton High Heavyweight Socks | K22: White | L22: X-Large | O22: 7.776 | R22: =IFERROR(VLOOKUP(E22,Sheet6!$A$2:$B$500,2,FALSE),0) -> 5 | S22: =IFERROR(VLOOKUP(E22,Sheet6!$C$2:$D$35017,2,FALSE),0) -> 90 | U22: =IFERROR(VLOOKUP(E22,Sheet2!$AA$1:$AB$975,2,FALSE),0) -> 0 | V22: =IFERROR(VLOOKUP(E22,Sheet2!$AC$1:$AD$975,2,FALSE),0) -> 0 | W22: =IFERROR(VLOOKUP(E22,Sheet2!$AE$1:$AF$975,2,FALSE),0) -> 0 | X22: =IFERROR(VLOOKUP(E22,Sheet2!$AG$1:$AH$975,2,FALSE),0) -> 0 | Z22: =IFERROR(VLOOKUP(F22,Sheet2!$AA$1:$AB$975,2,FALSE),0) -> 0 | AA22: =IFERROR(VLOOKUP(F22,Sheet2!$AC$1:$AD$975,2,FALSE),0) -> 0 | AB22: =IFERROR(VLOOKUP(F22,Sheet2!$AE$2:$AF$6539,2,FALSE),0) -> 0 | AC22: =IFERROR(VLOOKUP(F22,Sheet2!$AG$2:$AH$6539,2,FALSE),0) -> 0 | AE22: 35 | AF22: 0 | AG22: 0 | AH22: 0 | AI22: 0 | AJ22: =SUM(AE22+AI22) -> 35 | AK22: =SUM(AJ22*O22) -> 272.16 | AL22: 0 | AM22: 0
A23: GoBros | B23: 46173 | D23: 048323013796 | E23: WIGF1061_051_wht_0 | F23: ZZWIGF1061_051_wht_0 | G23: #N/A | H23: FBM Only | I23: F1061 | J23: Wigwam Master Lightweight Crew Socks | K23: White | L23: 10 | O23: 7.776 | R23: =IFERROR(VLOOKUP(E23,Sheet6!$A$2:$B$500,2,FALSE),0) -> 0 | S23: =IFERROR(VLOOKUP(E23,Sheet6!$C$2:$D$35017,2,FALSE),0) -> 0 | U23: =IFERROR(VLOOKUP(E23,Sheet2!$AA$1:$AB$975,2,FALSE),0) -> 0 | V23: =IFERROR(VLOOKUP(E23,Sheet2!$AC$1:$AD$975,2,FALSE),0) -> 0 | W23: =IFERROR(VLOOKUP(E23,Sheet2!$AE$1:$AF$975,2,FALSE),0) -> 0 | X23: =IFERROR(VLOOKUP(E23,Sheet2!$AG$1:$AH$975,2,FALSE),0) -> 0 | Z23: =IFERROR(VLOOKUP(F23,Sheet2!$AA$1:$AB$975,2,FALSE),0) -> 0 | AA23: =IFERROR(VLOOKUP(F23,Sheet2!$AC$1:$AD$975,2,FALSE),0) -> 0 | AB23: =IFERROR(VLOOKUP(F23,Sheet2!$AE$2:$AF$6539,2,FALSE),0) -> 0 | AC23: =IFERROR(VLOOKUP(F23,Sheet2!$AG$2:$AH$6539,2,FALSE),0) -> 0 | AE23: 70 | AF23: 0 | AG23: 6 | AH23: 0 | AI23: 6 | AJ23: =SUM(AE23+AI23) -> 76 | AK23: =SUM(AJ23*O23) -> 590.976 | AL23: 6 | AM23: 0
A24: GoBros | B24: 46173 | D24: 048323013802 | E24: WIGF1061_051_wht_1 | F24: ZZWIGF1061_051_wht_1 | G24: #N/A | H24: FBM Only | I24: F1061 | J24: Wigwam Master Lightweight Crew Socks | K24: White | L24: 11 | O24: 7.776 | R24: =IFERROR(VLOOKUP(E24,Sheet6!$A$2:$B$500,2,FALSE),0) -> 0 | S24: =IFERROR(VLOOKUP(E24,Sheet6!$C$2:$D$35017,2,FALSE),0) -> 0 | U24: =IFERROR(VLOOKUP(E24,Sheet2!$AA$1:$AB$975,2,FALSE),0) -> 0 | V24: =IFERROR(VLOOKUP(E24,Sheet2!$AC$1:$AD$975,2,FALSE),0) -> 0 | W24: =IFERROR(VLOOKUP(E24,Sheet2!$AE$1:$AF$975,2,FALSE),0) -> 0 | X24: =IFERROR(VLOOKUP(E24,Sheet2!$AG$1:$AH$975,2,FALSE),0) -> 0 | Z24: =IFERROR(VLOOKUP(F24,Sheet2!$AA$1:$AB$975,2,FALSE),0) -> 0 | AA24: =IFERROR(VLOOKUP(F24,Sheet2!$AC$1:$AD$975,2,FALSE),0) -> 0 | AB24: =IFERROR(VLOOKUP(F24,Sheet2!$AE$2:$AF$6539,2,FALSE),0) -> 0 | AC24: =IFERROR(VLOOKUP(F24,Sheet2!$AG$2:$AH$6539,2,FALSE),0) -> 0 | AE24: 66 | AF24: 0 | AG24: 0 | AH24: 0 | AI24: 0 | AJ24: =SUM(AE24+AI24) -> 66 | AK24: =SUM(AJ24*O24) -> 513.216 | AL24: 0 | AM24: 0
A25: GoBros | B25: 46173 | D25: 048323013819 | E25: WIGF1061_051_wht_2 | F25: ZZWIGF1061_051_wht_2 | G25: #N/A | H25: FBM Only | I25: F1061 | J25: Wigwam Master Lightweight Crew Socks | K25: White | L25: 12 | O25: 7.776 | R25: =IFERROR(VLOOKUP(E25,Sheet6!$A$2:$B$500,2,FALSE),0) -> 0 | S25: =IFERROR(VLOOKUP(E25,Sheet6!$C$2:$D$35017,2,FALSE),0) -> 0 | U25: =IFERROR(VLOOKUP(E25,Sheet2!$AA$1:$AB$975,2,FALSE),0) -> 0 | V25: =IFERROR(VLOOKUP(E25,Sheet2!$AC$1:$AD$975,2,FALSE),0) -> 0 | W25: =IFERROR(VLOOKUP(E25,Sheet2!$AE$1:$AF$975,2,FALSE),0) -> 0 | X25: =IFERROR(VLOOKUP(E25,Sheet2!$AG$1:$AH$975,2,FALSE),0) -> 0 | Z25: =IFERROR(VLOOKUP(F25,Sheet2!$AA$1:$AB$975,2,FALSE),0) -> 1 | AA25: =IFERROR(VLOOKUP(F25,Sheet2!$AC$1:$AD$975,2,FALSE),0) -> 18 | AB25: =IFERROR(VLOOKUP(F25,Sheet2!$AE$2:$AF$6539,2,FALSE),0) -> 28 | AC25: =IFERROR(VLOOKUP(F25,Sheet2!$AG$2:$AH$6539,2,FALSE),0) -> 0.5484 | AE25: 62 | AF25: 8 | AG25: 0 | AH25: 0 | AI25: 8 | AJ25: =SUM(AE25+AI25) -> 70 | AK25: =SUM(AJ25*O25) -> 544.32 | AL25: 0 | AM25: 0
A26: GoBros | B26: 46173 | D26: 048323013826 | E26: WIGF1061_051_wht_3 | F26: ZZWIGF1061_051_wht_3 | G26: #N/A | H26: FBM Only | I26: F1061 | J26: Wigwam Master Lightweight Crew Socks | K26: White | L26: 13 | O26: 7.776 | R26: =IFERROR(VLOOKUP(E26,Sheet6!$A$2:$B$500,2,FALSE),0) -> 0 | S26: =IFERROR(VLOOKUP(E26,Sheet6!$C$2:$D$35017,2,FALSE),0) -> 0 | U26: =IFERROR(VLOOKUP(E26,Sheet2!$AA$1:$AB$975,2,FALSE),0) -> 8 | V26: =IFERROR(VLOOKUP(E26,Sheet2!$AC$1:$AD$975,2,FALSE),0) -> 144 | W26: =IFERROR(VLOOKUP(E26,Sheet2!$AE$1:$AF$975,2,FALSE),0) -> 20 | X26: =IFERROR(VLOOKUP(E26,Sheet2!$AG$1:$AH$975,2,FALSE),0) -> 0.9688 | Z26: =IFERROR(VLOOKUP(F26,Sheet2!$AA$1:$AB$975,2,FALSE),0) -> 0 | AA26: =IFERROR(VLOOKUP(F26,Sheet2!$AC$1:$AD$975,2,FALSE),0) -> 0 | AB26: =IFERROR(VLOOKUP(F26,Sheet2!$AE$2:$AF$6539,2,FALSE),0) -> 0 | AC26: =IFERROR(VLOOKUP(F26,Sheet2!$AG$2:$AH$6539,2,FALSE),0) -> 0 | AE26: 46 | AF26: 0 | AG26: 0 | AH26: 0 | AI26: 0 | AJ26: =SUM(AE26+AI26) -> 46 | AK26: =SUM(AJ26*O26) -> 357.696 | AL26: 0 | AM26: 0
A27: GoBros | B27: 46173 | D27: 048323013833 | E27: WIGF1061_051_wht_4 | F27: ZZWIGF1061_051_wht_4 | G27: #N/A | H27: FBM Only | I27: F1061 | J27: Wigwam Master Lightweight Crew Socks | K27: White | L27: 14 | O27: 7.776 | R27: =IFERROR(VLOOKUP(E27,Sheet6!$A$2:$B$500,2,FALSE),0) -> 0 | S27: =IFERROR(VLOOKUP(E27,Sheet6!$C$2:$D$35017,2,FALSE),0) -> 0 | U27: =IFERROR(VLOOKUP(E27,Sheet2!$AA$1:$AB$975,2,FALSE),0) -> 0 | V27: =IFERROR(VLOOKUP(E27,Sheet2!$AC$1:$AD$975,2,FALSE),0) -> 0 | W27: =IFERROR(VLOOKUP(E27,Sheet2!$AE$1:$AF$975,2,FALSE),0) -> 0 | X27: =IFERROR(VLOOKUP(E27,Sheet2!$AG$1:$AH$975,2,FALSE),0) -> 0 | Z27: =IFERROR(VLOOKUP(F27,Sheet2!$AA$1:$AB$975,2,FALSE),0) -> 0 | AA27: =IFERROR(VLOOKUP(F27,Sheet2!$AC$1:$AD$975,2,FALSE),0) -> 0 | AB27: =IFERROR(VLOOKUP(F27,Sheet2!$AE$2:$AF$6539,2,FALSE),0) -> 0 | AC27: =IFERROR(VLOOKUP(F27,Sheet2!$AG$2:$AH$6539,2,FALSE),0) -> 0 | AE27: 27 | AF27: 16 | AG27: 0 | AH27: 0 | AI27: 16 | AJ27: =SUM(AE27+AI27) -> 43 | AK27: =SUM(AJ27*O27) -> 334.368 | AL27: 0 | AM27: 0
A28: GoBros | B28: 46173 | D28: 048323573894 | E28: WIGF1061_052_blk_0 | F28: ZZWIGF1061_052_blk_0 | G28: #N/A | H28: FBM Only | I28: F1061 | J28: Wigwam Master Lightweight Crew Socks | K28: Black | L28: 10 | O28: 7.776 | R28: =IFERROR(VLOOKUP(E28,Sheet6!$A$2:$B$500,2,FALSE),0) -> 0 | S28: =IFERROR(VLOOKUP(E28,Sheet6!$C$2:$D$35017,2,FALSE),0) -> 0 | U28: =IFERROR(VLOOKUP(E28,Sheet2!$AA$1:$AB$975,2,FALSE),0) -> 0 | V28: =IFERROR(VLOOKUP(E28,Sheet2!$AC$1:$AD$975,2,FALSE),0) -> 0 | W28: =IFERROR(VLOOKUP(E28,Sheet2!$AE$1:$AF$975,2,FALSE),0) -> 0 | X28: =IFERROR(VLOOKUP(E28,Sheet2!$AG$1:$AH$975,2,FALSE),0) -> 0 | Z28: =IFERROR(VLOOKUP(F28,Sheet2!$AA$1:$AB$975,2,FALSE),0) -> 0 | AA28: =IFERROR(VLOOKUP(F28,Sheet2!$AC$1:$AD$975,2,FALSE),0) -> 0 | AB28: =IFERROR(VLOOKUP(F28,Sheet2!$AE$2:$AF$6539,2,FALSE),0) -> 0 | AC28: =IFERROR(VLOOKUP(F28,Sheet2!$AG$2:$AH$6539,2,FALSE),0) -> 0 | AE28: 12 | AF28: 6 | AG28: 0 | AH28: 0 | AI28: 6 | AJ28: =SUM(AE28+AI28) -> 18 | AK28: =SUM(AJ28*O28) -> 139.968 | AL28: 0 | AM28: 0
A29: GoBros | B29: 46173 | D29: 048323573900 | E29: WIGF1061_052_blk_1 | F29: ZZWIGF1061_052_blk_1 | G29: #N/A | H29: FBM Only | I29: F1061 | J29: Wigwam Master Lightweight Crew Socks | K29: Black | L29: 11 | O29: 7.776 | R29: =IFERROR(VLOOKUP(E29,Sheet6!$A$2:$B$500,2,FALSE),0) -> 0 | S29: =IFERROR(VLOOKUP(E29,Sheet6!$C$2:$D$35017,2,FALSE),0) -> 0 | U29: =IFERROR(VLOOKUP(E29,Sheet2!$AA$1:$AB$975,2,FALSE),0) -> 0 | V29: =IFERROR(VLOOKUP(E29,Sheet2!$AC$1:$AD$975,2,FALSE),0) -> 0 | W29: =IFERROR(VLOOKUP(E29,Sheet2!$AE$1:$AF$975,2,FALSE),0) -> 0 | X29: =IFERROR(VLOOKUP(E29,Sheet2!$AG$1:$AH$975,2,FALSE),0) -> 0 | Z29: =IFERROR(VLOOKUP(F29,Sheet2!$AA$1:$AB$975,2,FALSE),0) -> 0 | AA29: =IFERROR(VLOOKUP(F29,Sheet2!$AC$1:$AD$975,2,FALSE),0) -> 0 | AB29: =IFERROR(VLOOKUP(F29,Sheet2!$AE$2:$AF$6539,2,FALSE),0) -> 0 | AC29: =IFERROR(VLOOKUP(F29,Sheet2!$AG$2:$AH$6539,2,FALSE),0) -> 0 | AE29: 26 | AF29: 6 | AG29: 0 | AH29: 0 | AI29: 6 | AJ29: =SUM(AE29+AI29) -> 32 | AK29: =SUM(AJ29*O29) -> 248.832 | AL29: 0 | AM29: 0
A30: GoBros | B30: 46173 | D30: 048323573917 | E30: WIGF1061_052_blk_2 | F30: ZZWIGF1061_052_blk_2 | G30: #N/A | H30: FBM Only | I30: F1061 | J30: Wigwam Master Lightweight Crew Socks | K30: Black | L30: 12 | O30: 7.776 | R30: =IFERROR(VLOOKUP(E30,Sheet6!$A$2:$B$500,2,FALSE),0) -> 0 | S30: =IFERROR(VLOOKUP(E30,Sheet6!$C$2:$D$35017,2,FALSE),0) -> 0 | U30: =IFERROR(VLOOKUP(E30,Sheet2!$AA$1:$AB$975,2,FALSE),0) -> 0 | V30: =IFERROR(VLOOKUP(E30,Sheet2!$AC$1:$AD$975,2,FALSE),0) -> 0 | W30: =IFERROR(VLOOKUP(E30,Sheet2!$AE$1:$AF$975,2,FALSE),0) -> 0 | X30: =IFERROR(VLOOKUP(E30,Sheet2!$AG$1:$AH$975,2,FALSE),0) -> 0 | Z30: =IFERROR(VLOOKUP(F30,Sheet2!$AA$1:$AB$975,2,FALSE),0) -> 0 | AA30: =IFERROR(VLOOKUP(F30,Sheet2!$AC$1:$AD$975,2,FALSE),0) -> 0 | AB30: =IFERROR(VLOOKUP(F30,Sheet2!$AE$2:$AF$6539,2,FALSE),0) -> 0 | AC30: =IFERROR(VLOOKUP(F30,Sheet2!$AG$2:$AH$6539,2,FALSE),0) -> 0 | AE30: 19 | AF30: 18 | AG30: 0 | AH30: 0 | AI30: 18 | AJ30: =SUM(AE30+AI30) -> 37 | AK30: =SUM(AJ30*O30) -> 287.712 | AL30: 0 | AM30: 0
A31: GoBros | B31: 46173 | D31: 048323573924 | E31: WIGF1061_052_blk_3 | F31: ZZWIGF1061_052_blk_3 | G31: #N/A | H31: FBM Only | I31: F1061 | J31: Wigwam Master Lightweight Crew Socks | K31: Black | L31: 13 | O31: 7.776 | R31: =IFERROR(VLOOKUP(E31,Sheet6!$A$2:$B$500,2,FALSE),0) -> 0 | S31: =IFERROR(VLOOKUP(E31,Sheet6!$C$2:$D$35017,2,FALSE),0) -> 0 | U31: =IFERROR(VLOOKUP(E31,Sheet2!$AA$1:$AB$975,2,FALSE),0) -> 0 | V31: =IFERROR(VLOOKUP(E31,Sheet2!$AC$1:$AD$975,2,FALSE),0) -> 0 | W31: =IFERROR(VLOOKUP(E31,Sheet2!$AE$1:$AF$975,2,FALSE),0) -> 0 | X31: =IFERROR(VLOOKUP(E31,Sheet2!$AG$1:$AH$975,2,FALSE),0) -> 0 | Z31: =IFERROR(VLOOKUP(F31,Sheet2!$AA$1:$AB$975,2,FALSE),0) -> 0 | AA31: =IFERROR(VLOOKUP(F31,Sheet2!$AC$1:$AD$975,2,FALSE),0) -> 0 | AB31: =IFERROR(VLOOKUP(F31,Sheet2!$AE$2:$AF$6539,2,FALSE),0) -> 0 | AC31: =IFERROR(VLOOKUP(F31,Sheet2!$AG$2:$AH$6539,2,FALSE),0) -> 0 | AE31: 63 | AF31: 2 | AG31: 0 | AH31: 0 | AI31: 2 | AJ31: =SUM(AE31+AI31) -> 65 | AK31: =SUM(AJ31*O31) -> 505.44 | AL31: 0 | AM31: 0
A32: GoBros | B32: 46173 | D32: 048323014090 | E32: WIGF1071_051_wht_0 | F32: ZZWIGF1071_051_wht_0 | G32: #N/A | H32: FBA | I32: F1071 | J32: Wigwam 622 Socks | K32: White | L32: Med | O32: 8.64 | R32: =IFERROR(VLOOKUP(E32,Sheet6!$A$2:$B$500,2,FALSE),0) -> 0 | S32: =IFERROR(VLOOKUP(E32,Sheet6!$C$2:$D$35017,2,FALSE),0) -> 0 | U32: =IFERROR(VLOOKUP(E32,Sheet2!$AA$1:$AB$975,2,FALSE),0) -> 0 | V32: =IFERROR(VLOOKUP(E32,Sheet2!$AC$1:$AD$975,2,FALSE),0) -> 0 | W32: =IFERROR(VLOOKUP(E32,Sheet2!$AE$1:$AF$975,2,FALSE),0) -> 0 | X32: =IFERROR(VLOOKUP(E32,Sheet2!$AG$1:$AH$975,2,FALSE),0) -> 0 | Z32: =IFERROR(VLOOKUP(F32,Sheet2!$AA$1:$AB$975,2,FALSE),0) -> 11 | AA32: =IFERROR(VLOOKUP(F32,Sheet2!$AC$1:$AD$975,2,FALSE),0) -> 219.89 | AB32: =IFERROR(VLOOKUP(F32,Sheet2!$AE$2:$AF$6539,2,FALSE),0) -> 69 | AC32: =IFERROR(VLOOKUP(F32,Sheet2!$AG$2:$AH$6539,2,FALSE),0) -> 1 | AE32: 0 | AF32: 13 | AG32: 0 | AH32: 0 | AI32: 13 | AJ32: =SUM(AE32+AI32) -> 13 | AK32: =SUM(AJ32*O32) -> 112.32 | AL32: 12 | AM32: 12
A33: GoBros | B33: 46173 | D33: 048323014083 | E33: WIGF1071_051_wht_1 | F33: ZZWIGF1071_051_wht_1 | G33: #N/A | H33: FBA | I33: F1071 | J33: Wigwam 622 Socks | K33: White | L33: Large | O33: 8.64 | R33: =IFERROR(VLOOKUP(E33,Sheet6!$A$2:$B$500,2,FALSE),0) -> 0 | S33: =IFERROR(VLOOKUP(E33,Sheet6!$C$2:$D$35017,2,FALSE),0) -> 0 | U33: =IFERROR(VLOOKUP(E33,Sheet2!$AA$1:$AB$975,2,FALSE),0) -> 0 | V33: =IFERROR(VLOOKUP(E33,Sheet2!$AC$1:$AD$975,2,FALSE),0) -> 0 | W33: =IFERROR(VLOOKUP(E33,Sheet2!$AE$1:$AF$975,2,FALSE),0) -> 0 | X33: =IFERROR(VLOOKUP(E33,Sheet2!$AG$1:$AH$975,2,FALSE),0) -> 0 | Z33: =IFERROR(VLOOKUP(F33,Sheet2!$AA$1:$AB$975,2,FALSE),0) -> 12 | AA33: =IFERROR(VLOOKUP(F33,Sheet2!$AC$1:$AD$975,2,FALSE),0) -> 239.88 | AB33: =IFERROR(VLOOKUP(F33,Sheet2!$AE$2:$AF$6539,2,FALSE),0) -> 103 | AC33: =IFERROR(VLOOKUP(F33,Sheet2!$AG$2:$AH$6539,2,FALSE),0) -> 0.7823 | AE33: 24 | AF33: 1 | AG33: 6 | AH33: 1 | AI33: 8 | AJ33: =SUM(AE33+AI33) -> 32 | AK33: =SUM(AJ33*O33) -> 276.48 | AL33: 12 | AM33: 30
A34: GoBros | B34: 46173 | D34: 048323014106 | E34: WIGF1071_051_wht_2 | F34: ZZWIGF1071_051_wht_2 | G34: #N/A | H34: FBA | I34: F1071 | J34: Wigwam 622 Socks | K34: White | L34: X-Large | O34: 8.64 | R34: =IFERROR(VLOOKUP(E34,Sheet6!$A$2:$B$500,2,FALSE),0) -> 0 | S34: =IFERROR(VLOOKUP(E34,Sheet6!$C$2:$D$35017,2,FALSE),0) -> 0 | U34: =IFERROR(VLOOKUP(E34,Sheet2!$AA$1:$AB$975,2,FALSE),0) -> 0 | V34: =IFERROR(VLOOKUP(E34,Sheet2!$AC$1:$AD$975,2,FALSE),0) -> 0 | W34: =IFERROR(VLOOKUP(E34,Sheet2!$AE$1:$AF$975,2,FALSE),0) -> 0 | X34: =IFERROR(VLOOKUP(E34,Sheet2!$AG$1:$AH$975,2,FALSE),0) -> 0 | Z34: =IFERROR(VLOOKUP(F34,Sheet2!$AA$1:$AB$975,2,FALSE),0) -> 4 | AA34: =IFERROR(VLOOKUP(F34,Sheet2!$AC$1:$AD$975,2,FALSE),0) -> 79.96 | AB34: =IFERROR(VLOOKUP(F34,Sheet2!$AE$2:$AF$6539,2,FALSE),0) -> 42 | AC34: =IFERROR(VLOOKUP(F34,Sheet2!$AG$2:$AH$6539,2,FALSE),0) -> 0.2157 | AE34: 3 | AF34: 2 | AG34: 0 | AH34: 0 | AI34: 2 | AJ34: =SUM(AE34+AI34) -> 5 | AK34: =SUM(AJ34*O34) -> 43.2 | AL34: 6 | AM34: 0
A35: GoBros | B35: 46173 | D35: 048323014120 | E35: WIGF1071_052_blk_0 | F35: ZZWIGF1071_052_blk_0 | G35: #N/A | H35: FBM Only | I35: F1071 | J35: Wigwam 622 Socks | K35: Black | L35: Medium | O35: 8.64 | R35: =IFERROR(VLOOKUP(E35,Sheet6!$A$2:$B$500,2,FALSE),0) -> 0 | S35: =IFERROR(VLOOKUP(E35,Sheet6!$C$2:$D$35017,2,FALSE),0) -> 0 | U35: =IFERROR(VLOOKUP(E35,Sheet2!$AA$1:$AB$975,2,FALSE),0) -> 0 | V35: =IFERROR(VLOOKUP(E35,Sheet2!$AC$1:$AD$975,2,FALSE),0) -> 0 | W35: =IFERROR(VLOOKUP(E35,Sheet2!$AE$1:$AF$975,2,FALSE),0) -> 0 | X35: =IFERROR(VLOOKUP(E35,Sheet2!$AG$1:$AH$975,2,FALSE),0) -> 0 | Z35: =IFERROR(VLOOKUP(F35,Sheet2!$AA$1:$AB$975,2,FALSE),0) -> 1 | AA35: =IFERROR(VLOOKUP(F35,Sheet2!$AC$1:$AD$975,2,FALSE),0) -> 19.99 | AB35: =IFERROR(VLOOKUP(F35,Sheet2!$AE$2:$AF$6539,2,FALSE),0) -> 26 | AC35: =IFERROR(VLOOKUP(F35,Sheet2!$AG$2:$AH$6539,2,FALSE),0) -> 0.4286 | AE35: 15 | AF35: 23 | AG35: 0 | AH35: 1 | AI35: 24 | AJ35: =SUM(AE35+AI35) -> 39 | AK35: =SUM(AJ35*O35) -> 336.96 | AL35: 0 | AM35: 0
A36: GoBros | B36: 46173 | D36: 048323014113 | E36: WIGF1071_052_blk_1 | F36: ZZWIGF1071_052_blk_1 | G36: B000G7W9CO | H36: FBM Only | I36: F1071 | J36: Wigwam 622 Socks | K36: Black | L36: Large | O36: 8.64 | R36: =IFERROR(VLOOKUP(E36,Sheet6!$A$2:$B$500,2,FALSE),0) -> 0 | S36: =IFERROR(VLOOKUP(E36,Sheet6!$C$2:$D$35017,2,FALSE),0) -> 0 | U36: =IFERROR(VLOOKUP(E36,Sheet2!$AA$1:$AB$975,2,FALSE),0) -> 0 | V36: =IFERROR(VLOOKUP(E36,Sheet2!$AC$1:$AD$975,2,FALSE),0) -> 0 | W36: =IFERROR(VLOOKUP(E36,Sheet2!$AE$1:$AF$975,2,FALSE),0) -> 0 | X36: =IFERROR(VLOOKUP(E36,Sheet2!$AG$1:$AH$975,2,FALSE),0) -> 0 | Z36: =IFERROR(VLOOKUP(F36,Sheet2!$AA$1:$AB$975,2,FALSE),0) -> 1 | AA36: =IFERROR(VLOOKUP(F36,Sheet2!$AC$1:$AD$975,2,FALSE),0) -> 19.99 | AB36: =IFERROR(VLOOKUP(F36,Sheet2!$AE$2:$AF$6539,2,FALSE),0) -> 25 | AC36: =IFERROR(VLOOKUP(F36,Sheet2!$AG$2:$AH$6539,2,FALSE),0) -> 0.3 | AE36: 27 | AF36: 1 | AG36: 0 | AH36: 0 | AI36: 1 | AJ36: =SUM(AE36+AI36) -> 28 | AK36: =SUM(AJ36*O36) -> 241.92 | AL36: 12 | AM36: 12
A37: GoBros | B37: 46173 | D37: 048323014328 | E37: WIGF1072_051_wht_0 | F37: ZZWIGF1072_051_wht_0 | G37: #N/A | H37: FBM Only | I37: F1072 | J37: Wigwam Advantage Crew Socks | K37: White | L37: Medium | O37: 6.048 | R37: =IFERROR(VLOOKUP(E37,Sheet6!$A$2:$B$500,2,FALSE),0) -> 0 | S37: =IFERROR(VLOOKUP(E37,Sheet6!$C$2:$D$35017,2,FALSE),0) -> 0 | U37: =IFERROR(VLOOKUP(E37,Sheet2!$AA$1:$AB$975,2,FALSE),0) -> 0 | V37: =IFERROR(VLOOKUP(E37,Sheet2!$AC$1:$AD$975,2,FALSE),0) -> 0 | W37: =IFERROR(VLOOKUP(E37,Sheet2!$AE$1:$AF$975,2,FALSE),0) -> 0 | X37: =IFERROR(VLOOKUP(E37,Sheet2!$AG$1:$AH$975,2,FALSE),0) -> 0 | Z37: =IFERROR(VLOOKUP(F37,Sheet2!$AA$1:$AB$975,2,FALSE),0) -> 0 | AA37: =IFERROR(VLOOKUP(F37,Sheet2!$AC$1:$AD$975,2,FALSE),0) -> 0 | AB37: =IFERROR(VLOOKUP(F37,Sheet2!$AE$2:$AF$6539,2,FALSE),0) -> 0 | AC37: =IFERROR(VLOOKUP(F37,Sheet2!$AG$2:$AH$6539,2,FALSE),0) -> 0 | AE37: 67 | AF37: 0 | AG37: 0 | AH37: 0 | AI37: 0 | AJ37: =SUM(AE37+AI37) -> 67 | AK37: =SUM(AJ37*O37) -> 405.216 | AL37: 0 | AM37: 0
A38: GoBros | B38: 46173 | D38: 048323014311 | E38: WIGF1072_051_wht_1 | F38: ZZWIGF1072_051_wht_1 | G38: #N/A | H38: FBA | I38: F1072 | J38: Wigwam Advantage Crew Socks | K38: White | L38: Large | O38: 6.048 | R38: =IFERROR(VLOOKUP(E38,Sheet6!$A$2:$B$500,2,FALSE),0) -> 5 | S38: =IFERROR(VLOOKUP(E38,Sheet6!$C$2:$D$35017,2,FALSE),0) -> 65.8 | U38: =IFERROR(VLOOKUP(E38,Sheet2!$AA$1:$AB$975,2,FALSE),0) -> 0 | V38: =IFERROR(VLOOKUP(E38,Sheet2!$AC$1:$AD$975,2,FALSE),0) -> 0 | W38: =IFERROR(VLOOKUP(E38,Sheet2!$AE$1:$AF$975,2,FALSE),0) -> 0 | X38: =IFERROR(VLOOKUP(E38,Sheet2!$AG$1:$AH$975,2,FALSE),0) -> 0 | Z38: =IFERROR(VLOOKUP(F38,Sheet2!$AA$1:$AB$975,2,FALSE),0) -> 0 | AA38: =IFERROR(VLOOKUP(F38,Sheet2!$AC$1:$AD$975,2,FALSE),0) -> 0 | AB38: =IFERROR(VLOOKUP(F38,Sheet2!$AE$2:$AF$6539,2,FALSE),0) -> 0 | AC38: =IFERROR(VLOOKUP(F38,Sheet2!$AG$2:$AH$6539,2,FALSE),0) -> 0 | AE38: 69 | AF38: 0 | AG38: 0 | AH38: 0 | AI38: 0 | AJ38: =SUM(AE38+AI38) -> 69 | AK38: =SUM(AJ38*O38) -> 417.312 | AL38: 0 | AM38: 0
A39: GoBros | B39: 46173 | D39: 048323014335 | E39: WIGF1072_051_wht_2 | F39: ZZWIGF1072_051_wht_2 | G39: #N/A | H39: FBA | I39: F1072 | J39: Wigwam Advantage Crew Socks | K39: White | L39: X-Large | O39: 6.048 | R39: =IFERROR(VLOOKUP(E39,Sheet6!$A$2:$B$500,2,FALSE),0) -> 0 | S39: =IFERROR(VLOOKUP(E39,Sheet6!$C$2:$D$35017,2,FALSE),0) -> 0 | U39: =IFERROR(VLOOKUP(E39,Sheet2!$AA$1:$AB$975,2,FALSE),0) -> 2 | V39: =IFERROR(VLOOKUP(E39,Sheet2!$AC$1:$AD$975,2,FALSE),0) -> 28 | W39: =IFERROR(VLOOKUP(E39,Sheet2!$AE$1:$AF$975,2,FALSE),0) -> 84 | X39: =IFERROR(VLOOKUP(E39,Sheet2!$AG$1:$AH$975,2,FALSE),0) -> 0.9902 | Z39: =IFERROR(VLOOKUP(F39,Sheet2!$AA$1:$AB$975,2,FALSE),0) -> 0 | AA39: =IFERROR(VLOOKUP(F39,Sheet2!$AC$1:$AD$975,2,FALSE),0) -> 0 | AB39: =IFERROR(VLOOKUP(F39,Sheet2!$AE$2:$AF$6539,2,FALSE),0) -> 0 | AC39: =IFERROR(VLOOKUP(F39,Sheet2!$AG$2:$AH$6539,2,FALSE),0) -> 0 | AE39: 11 | AF39: 0 | AG39: 0 | AH39: 0 | AI39: 0 | AJ39: =SUM(AE39+AI39) -> 11 | AK39: =SUM(AJ39*O39) -> 66.528 | AL39: 0 | AM39: 0
A40: GoBros | B40: 46173 | D40: 048323015820 | E40: WIGF1086_051_nat_0 | F40: ZZWIGF1086_051_nat_0 | G40: #N/A | H40: FBA | I40: F1086 | J40: Wigwam 625 Wool Crew Socks | K40: Natural White | L40: Medium | O40: 9.9 | R40: =IFERROR(VLOOKUP(E40,Sheet6!$A$2:$B$500,2,FALSE),0) -> 2 | S40: =IFERROR(VLOOKUP(E40,Sheet6!$C$2:$D$35017,2,FALSE),0) -> 44 | U40: =IFERROR(VLOOKUP(E40,Sheet2!$AA$1:$AB$975,2,FALSE),0) -> 0 | V40: =IFERROR(VLOOKUP(E40,Sheet2!$AC$1:$AD$975,2,FALSE),0) -> 0 | W40: =IFERROR(VLOOKUP(E40,Sheet2!$AE$1:$AF$975,2,FALSE),0) -> 0 | X40: =IFERROR(VLOOKUP(E40,Sheet2!$AG$1:$AH$975,2,FALSE),0) -> 0 | Z40: =IFERROR(VLOOKUP(F40,Sheet2!$AA$1:$AB$975,2,FALSE),0) -> 32 | AA40: =IFERROR(VLOOKUP(F40,Sheet2!$AC$1:$AD$975,2,FALSE),0) -> 703.68 | AB40: =IFERROR(VLOOKUP(F40,Sheet2!$AE$2:$AF$6539,2,FALSE),0) -> 88 | AC40: =IFERROR(VLOOKUP(F40,Sheet2!$AG$2:$AH$6539,2,FALSE),0) -> 0.9116 | AE40: 34 | AF40: 64 | AG40: 0 | AH40: 1 | AI40: 65 | AJ40: =SUM(AE40+AI40) -> 99 | AK40: =SUM(AJ40*O40) -> 980.1 | AL40: 30 | AM40: 0
A41: GoBros | B41: 46173 | D41: 048323015813 | E41: WIGF1086_051_nat_1 | F41: ZZWIGF1086_051_nat_1 | G41: #N/A | H41: FBM Only | I41: F1086 | J41: Wigwam 625 Wool Crew Socks | K41: Natural White | L41: Large | O41: 9.9 | R41: =IFERROR(VLOOKUP(E41,Sheet6!$A$2:$B$500,2,FALSE),0) -> 0 | S41: =IFERROR(VLOOKUP(E41,Sheet6!$C$2:$D$35017,2,FALSE),0) -> 0 | U41: =IFERROR(VLOOKUP(E41,Sheet2!$AA$1:$AB$975,2,FALSE),0) -> 0 | V41: =IFERROR(VLOOKUP(E41,Sheet2!$AC$1:$AD$975,2,FALSE),0) -> 0 | W41: =IFERROR(VLOOKUP(E41,Sheet2!$AE$1:$AF$975,2,FALSE),0) -> 0 | X41: =IFERROR(VLOOKUP(E41,Sheet2!$AG$1:$AH$975,2,FALSE),0) -> 0 | Z41: =IFERROR(VLOOKUP(F41,Sheet2!$AA$1:$AB$975,2,FALSE),0) -> 5 | AA41: =IFERROR(VLOOKUP(F41,Sheet2!$AC$1:$AD$975,2,FALSE),0) -> 109.95 | AB41: =IFERROR(VLOOKUP(F41,Sheet2!$AE$2:$AF$6539,2,FALSE),0) -> 106 | AC41: =IFERROR(VLOOKUP(F41,Sheet2!$AG$2:$AH$6539,2,FALSE),0) -> 0.1989 | AE41: 0 | AF41: 0 | AG41: 2 | AH41: 0 | AI41: 2 | AJ41: =SUM(AE41+AI41) -> 2 | AK41: =SUM(AJ41*O41) -> 19.8 | AL41: 0 | AM41: 270
A42: GoBros | B42: 46173 | D42: 048323015837 | E42: WIGF1086_051_nat_2 | F42: ZZWIGF1086_051_nat_2 | G42: #N/A | H42: FBM Only | I42: F1086 | J42: Wigwam 625 Wool Crew Socks | K42: Natural White | L42: X-Large | O42: 9.9 | R42: =IFERROR(VLOOKUP(E42,Sheet6!$A$2:$B$500,2,FALSE),0) -> 1 | S42: =IFERROR(VLOOKUP(E42,Sheet6!$C$2:$D$35017,2,FALSE),0) -> 22 | U42: =IFERROR(VLOOKUP(E42,Sheet2!$AA$1:$AB$975,2,FALSE),0) -> 4 | V42: =IFERROR(VLOOKUP(E42,Sheet2!$AC$1:$AD$975,2,FALSE),0) -> 87.96 | W42: =IFERROR(VLOOKUP(E42,Sheet2!$AE$1:$AF$975,2,FALSE),0) -> 191 | X42: =IFERROR(VLOOKUP(E42,Sheet2!$AG$1:$AH$975,2,FALSE),0) -> 0.3222 | Z42: =IFERROR(VLOOKUP(F42,Sheet2!$AA$1:$AB$975,2,FALSE),0) -> 2 | AA42: =IFERROR(VLOOKUP(F42,Sheet2!$AC$1:$AD$975,2,FALSE),0) -> 43.98 | AB42: =IFERROR(VLOOKUP(F42,Sheet2!$AE$2:$AF$6539,2,FALSE),0) -> 191 | AC42: =IFERROR(VLOOKUP(F42,Sheet2!$AG$2:$AH$6539,2,FALSE),0) -> 0.3222 | AE42: 58 | AF42: 0 | AG42: 6 | AH42: 0 | AI42: 6 | AJ42: =SUM(AE42+AI42) -> 64 | AK42: =SUM(AJ42*O42) -> 633.6 | AL42: 54 | AM42: 0
A43: GoBros | B43: 46173 | D43: 048323666077 | E43: WIGF1091_052_blk_2 | F43: ZZWIGF1091_052_blk_2 | G43: #N/A | H43: FBM Only | I43: F1091 | J43: Wigwam The Icon Lightweight Crew Socks | K43: Black | L43: Large | O43: 8.64 | R43: =IFERROR(VLOOKUP(E43,Sheet6!$A$2:$B$500,2,FALSE),0) -> 0 | S43: =IFERROR(VLOOKUP(E43,Sheet6!$C$2:$D$35017,2,FALSE),0) -> 0 | U43: =IFERROR(VLOOKUP(E43,Sheet2!$AA$1:$AB$975,2,FALSE),0) -> 0 | V43: =IFERROR(VLOOKUP(E43,Sheet2!$AC$1:$AD$975,2,FALSE),0) -> 0 | W43: =IFERROR(VLOOKUP(E43,Sheet2!$AE$1:$AF$975,2,FALSE),0) -> 0 | X43: =IFERROR(VLOOKUP(E43,Sheet2!$AG$1:$AH$975,2,FALSE),0) -> 0 | Z43: =IFERROR(VLOOKUP(F43,Sheet2!$AA$1:$AB$975,2,FALSE),0) -> 5 | AA43: =IFERROR(VLOOKUP(F43,Sheet2!$AC$1:$AD$975,2,FALSE),0) -> 100 | AB43: =IFERROR(VLOOKUP(F43,Sheet2!$AE$2:$AF$6539,2,FALSE),0) -> 24 | AC43: =IFERROR(VLOOKUP(F43,Sheet2!$AG$2:$AH$6539,2,FALSE),0) -> 1 | AE43: 15 | AF43: 6 | AG43: 0 | AH43: 0 | AI43: 6 | AJ43: =SUM(AE43+AI43) -> 21 | AK43: =SUM(AJ43*O43) -> 181.44 | AL43: 6 | AM43: 12
A44: GoBros | B44: 46173 | D44: 048323666084 | E44: WIGF1091_115_nat_1 | F44: ZZWIGF1091_115_nat_1 | G44: #N/A | H44: FBM Only | I44: F1091 | J44: Wigwam The Icon Lightweight Crew Socks | K44: White | L44: Medium | O44: 8.64 | R44: =IFERROR(VLOOKUP(E44,Sheet6!$A$2:$B$500,2,FALSE),0) -> 0 | S44: =IFERROR(VLOOKUP(E44,Sheet6!$C$2:$D$35017,2,FALSE),0) -> 0 | U44: =IFERROR(VLOOKUP(E44,Sheet2!$AA$1:$AB$975,2,FALSE),0) -> 0 | V44: =IFERROR(VLOOKUP(E44,Sheet2!$AC$1:$AD$975,2,FALSE),0) -> 0 | W44: =IFERROR(VLOOKUP(E44,Sheet2!$AE$1:$AF$975,2,FALSE),0) -> 0 | X44: =IFERROR(VLOOKUP(E44,Sheet2!$AG$1:$AH$975,2,FALSE),0) -> 0 | Z44: =IFERROR(VLOOKUP(F44,Sheet2!$AA$1:$AB$975,2,FALSE),0) -> 0 | AA44: =IFERROR(VLOOKUP(F44,Sheet2!$AC$1:$AD$975,2,FALSE),0) -> 0 | AB44: =IFERROR(VLOOKUP(F44,Sheet2!$AE$2:$AF$6539,2,FALSE),0) -> 0 | AC44: =IFERROR(VLOOKUP(F44,Sheet2!$AG$2:$AH$6539,2,FALSE),0) -> 0 | AE44: 0 | AF44: 0 | AG44: 0 | AH44: 0 | AI44: 0 | AJ44: =SUM(AE44+AI44) -> 0 | AK44: =SUM(AJ44*O44) -> 0 | AL44: 0 | AM44: 0
A45: GoBros | B45: 46173 | D45: 048323666091 | E45: WIGF1091_115_nat_2 | F45: ZZWIGF1091_115_nat_2 | G45: #N/A | H45: FBM Only | I45: F1091 | J45: Wigwam The Icon Lightweight Crew Socks | K45: White | L45: Large | O45: 8.64 | R45: =IFERROR(VLOOKUP(E45,Sheet6!$A$2:$B$500,2,FALSE),0) -> 0 | S45: =IFERROR(VLOOKUP(E45,Sheet6!$C$2:$D$35017,2,FALSE),0) -> 0 | U45: =IFERROR(VLOOKUP(E45,Sheet2!$AA$1:$AB$975,2,FALSE),0) -> 0 | V45: =IFERROR(VLOOKUP(E45,Sheet2!$AC$1:$AD$975,2,FALSE),0) -> 0 | W45: =IFERROR(VLOOKUP(E45,Sheet2!$AE$1:$AF$975,2,FALSE),0) -> 0 | X45: =IFERROR(VLOOKUP(E45,Sheet2!$AG$1:$AH$975,2,FALSE),0) -> 0 | Z45: =IFERROR(VLOOKUP(F45,Sheet2!$AA$1:$AB$975,2,FALSE),0) -> 0 | AA45: =IFERROR(VLOOKUP(F45,Sheet2!$AC$1:$AD$975,2,FALSE),0) -> 0 | AB45: =IFERROR(VLOOKUP(F45,Sheet2!$AE$2:$AF$6539,2,FALSE),0) -> 0 | AC45: =IFERROR(VLOOKUP(F45,Sheet2!$AG$2:$AH$6539,2,FALSE),0) -> 0 | AE45: 6 | AF45: 9 | AG45: 0 | AH45: 0 | AI45: 9 | AJ45: =SUM(AE45+AI45) -> 15 | AK45: =SUM(AJ45*O45) -> 129.6 | AL45: 0 | AM45: 0
A46: GoBros | B46: 46173 | D46: 048323187701 | E46: WIGF1140_052_bla_1 | F46: ZZWIGF1140_052_bla_1 | G46: #N/A | H46: FBM Only | I46: F1140 | J46: Wigwam At Work Steel Toe Heavyweight Socks | K46: Black | L46: Medium | O46: 6.912 | R46: =IFERROR(VLOOKUP(E46,Sheet6!$A$2:$B$500,2,FALSE),0) -> 0 | S46: =IFERROR(VLOOKUP(E46,Sheet6!$C$2:$D$35017,2,FALSE),0) -> 0 | U46: =IFERROR(VLOOKUP(E46,Sheet2!$AA$1:$AB$975,2,FALSE),0) -> 0 | V46: =IFERROR(VLOOKUP(E46,Sheet2!$AC$1:$AD$975,2,FALSE),0) -> 0 | W46: =IFERROR(VLOOKUP(E46,Sheet2!$AE$1:$AF$975,2,FALSE),0) -> 0 | X46: =IFERROR(VLOOKUP(E46,Sheet2!$AG$1:$AH$975,2,FALSE),0) -> 0 | Z46: =IFERROR(VLOOKUP(F46,Sheet2!$AA$1:$AB$975,2,FALSE),0) -> 0 | AA46: =IFERROR(VLOOKUP(F46,Sheet2!$AC$1:$AD$975,2,FALSE),0) -> 0 | AB46: =IFERROR(VLOOKUP(F46,Sheet2!$AE$2:$AF$6539,2,FALSE),0) -> 0 | AC46: =IFERROR(VLOOKUP(F46,Sheet2!$AG$2:$AH$6539,2,FALSE),0) -> 0 | AE46: 0 | AF46: 0 | AG46: 0 | AH46: 0 | AI46: 0 | AJ46: =SUM(AE46+AI46) -> 0 | AK46: =SUM(AJ46*O46) -> 0 | AL46: 0 | AM46: 0
A47: GoBros | B47: 46173 | D47: 048323187718 | E47: WIGF1140_052_bla_2 | F47: ZZWIGF1140_052_bla_2 | G47: #N/A | H47: FBM Only | I47: F1140 | J47: Wigwam At Work Steel Toe Heavyweight Socks | K47: Black | L47: Large | O47: 6.912 | R47: =IFERROR(VLOOKUP(E47,Sheet6!$A$2:$B$500,2,FALSE),0) -> 0 | S47: =IFERROR(VLOOKUP(E47,Sheet6!$C$2:$D$35017,2,FALSE),0) -> 0 | U47: =IFERROR(VLOOKUP(E47,Sheet2!$AA$1:$AB$975,2,FALSE),0) -> 0 | V47: =IFERROR(VLOOKUP(E47,Sheet2!$AC$1:$AD$975,2,FALSE),0) -> 0 | W47: =IFERROR(VLOOKUP(E47,Sheet2!$AE$1:$AF$975,2,FALSE),0) -> 0 | X47: =IFERROR(VLOOKUP(E47,Sheet2!$AG$1:$AH$975,2,FALSE),0) -> 0 | Z47: =IFERROR(VLOOKUP(F47,Sheet2!$AA$1:$AB$975,2,FALSE),0) -> 0 | AA47: =IFERROR(VLOOKUP(F47,Sheet2!$AC$1:$AD$975,2,FALSE),0) -> 0 | AB47: =IFERROR(VLOOKUP(F47,Sheet2!$AE$2:$AF$6539,2,FALSE),0) -> 0 | AC47: =IFERROR(VLOOKUP(F47,Sheet2!$AG$2:$AH$6539,2,FALSE),0) -> 0 | AE47: 25 | AF47: 0 | AG47: 0 | AH47: 0 | AI47: 0 | AJ47: =SUM(AE47+AI47) -> 25 | AK47: =SUM(AJ47*O47) -> 172.8 | AL47: 0 | AM47: 0
...

Sheet Sheet6
A1: Product variant SKU | B1: Net items sold | C1: Product variant SKU | D1: Net sales | H1: Product title | I1: Product variant title | J1: Product variant SKU | K1: Net items sold | L1: Gross sales | M1: Discounts | N1: Returns | O1: Net sales | P1: Taxes | Q1: Total sales
A2: WIGF1019_051_wht_0 | B2: 7 | C2: WIGF1019_051_wht_0 | D2: 105 | H2: Wigwam 7-Footer Extra Tall Socks | I2: One Size Fits Most / White | J2: WIGF1019_051_wht_0 | K2: 7 | L2: 105 | M2: 0 | N2: 0 | O2: 105 | P2: 7.24 | Q2: 112.24
A3: WIGF1054_052_bla_3 | B3: 3 | C3: WIGF1054_052_bla_3 | D3: 39 | H3: Wigwam Volley Midweight Crew Socks | I3: X-Large / Black | J3: WIGF1054_052_bla_3 | K3: 3 | L3: 39 | M3: 0 | N3: 0 | O3: 39 | P3: 1.56 | Q3: 40.56
A4: WIGF1055_051_wht_1 | B4: 12 | C4: WIGF1055_051_wht_1 | D4: 180 | H4: Wigwam King Cotton Heavyweight Crew Socks | I4: Large / White | J4: WIGF1055_051_wht_1 | K4: 12 | L4: 180 | M4: 0 | N4: 0 | O4: 180 | P4: 11.27 | Q4: 191.27
A5: WIGF1055_051_wht_2 | B5: 8 | C5: WIGF1055_051_wht_2 | D5: 117.75 | H5: Wigwam King Cotton Heavyweight Crew Socks | I5: X-Large / White | J5: WIGF1055_051_wht_2 | K5: 8 | L5: 120 | M5: -2.25 | N5: 0 | O5: 117.75 | P5: 4.95 | Q5: 122.7
A6: WIGF1055_052_blk_1 | B6: 9 | C6: WIGF1055_052_blk_1 | D6: 135 | H6: Wigwam King Cotton Heavyweight Crew Socks | I6: Large / Black | J6: WIGF1055_052_blk_1 | K6: 9 | L6: 135 | M6: 0 | N6: 0 | O6: 135 | P6: 8.1 | Q6: 143.1
A7: WIGF1055_052_blk_2 | B7: 3 | C7: WIGF1055_052_blk_2 | D7: 45 | H7: Wigwam King Cotton Heavyweight Crew Socks | I7: X-Large / Black | J7: WIGF1055_052_blk_2 | K7: 3 | L7: 45 | M7: 0 | N7: 0 | O7: 45 | P7: 3.6 | Q7: 48.6
A8: WIGF1057_51_whi_1 | B8: 3 | C8: WIGF1057_51_whi_1 | D8: 36 | H8: Wigwam King Cotton High Heavyweight Socks | I8: Medium / White | J8: WIGF1057_51_whi_1 | K8: 3 | L8: 54 | M8: -18 | N8: 0 | O8: 36 | P8: 0 | Q8: 36
A9: WIGF1057_51_whi_2 | B9: 4 | C9: WIGF1057_51_whi_2 | D9: 72 | H9: Wigwam King Cotton High Heavyweight Socks | I9: Large / White | J9: WIGF1057_51_whi_2 | K9: 4 | L9: 72 | M9: 0 | N9: 0 | O9: 72 | P9: 4.36 | Q9: 76.36
A10: WIGF1057_51_whi_3 | B10: 5 | C10: WIGF1057_51_whi_3 | D10: 90 | H10: Wigwam King Cotton High Heavyweight Socks | I10: X-Large / White | J10: WIGF1057_51_whi_3 | K10: 5 | L10: 90 | M10: 0 | N10: 0 | O10: 90 | P10: 6.76 | Q10: 96.76
A11: WIGF1072_051_wht_1 | B11: 5 | C11: WIGF1072_051_wht_1 | D11: 65.8 | H11: Wigwam Advantage Crew Socks | I11: Large / White | J11: WIGF1072_051_wht_1 | K11: 5 | L11: 70 | M11: -4.2 | N11: 0 | O11: 65.8 | P11: 5.32 | Q11: 71.12
A12: WIGF1086_051_nat_0 | B12: 2 | C12: WIGF1086_051_nat_0 | D12: 44 | H12: Wigwam 625 Wool Crew Socks | I12: Medium / White | J12: WIGF1086_051_nat_0 | K12: 2 | L12: 44 | M12: 0 | N12: 0 | O12: 44 | P12: 0 | Q12: 44
A13: WIGF1086_051_nat_2 | B13: 1 | C13: WIGF1086_051_nat_2 | D13: 22 | H13: Wigwam 625 Wool Crew Socks | I13: X-Large / White | J13: WIGF1086_051_nat_2 | K13: 1 | L13: 22 | M13: 0 | N13: 0 | O13: 22 | P13: 0.96 | Q13: 22.96
... A80: WIGS9020_51_whi_3 | B80: 6 | C80: WIGS9020_51_whi_3 | D80: 204 | H80: Wigwam Super 60 Crew 6-Pack Midweight Cotton Socks | I80: X-Large / White | J80: WIGS9020_51_whi_3 | K80: 6 | L80: 204 | M80: 0 | N80: 0 | O80: 204 | P80: 6.72 | Q80: 210.72
AE107: x

Sheet Sheet2
A1: (Parent) ASIN | B1: (Child) ASIN | C1: Title | D1: SKU | E1: Sessions - Total | F1: Sessions - Total - B2B | G1: Session Percentage - Total | H1: Session Percentage - Total - B2B | I1: Page Views - Total | J1: Page Views - Total - B2B | K1: Page Views Percentage - Total | L1: Page Views Percentage - Total - B2B | M1: Featured Offer (Buy Box) Percentage | N1: Featured Offer (Buy Box) Percentage - B2B | O1: Units Ordered | P1: Units Ordered - B2B | Q1: Unit Session Percentage | R1: Unit Session Percentage - B2B | S1: Ordered Product Sales | T1: Ordered Product Sales - B2B | U1: Total Order Items | V1: Total Order Items - B2B | AA1: SKU | AB1: Units Ordered | AC1: SKU | AD1: Ordered Product Sales | AE1: SKU | AF1: Sessions - Total | AG1: SKU | AH1: Featured Offer (Buy Box) Percentage
A2: B07BRBQ5FP | B2: B000ARG1KQ | C2: Wigwam 7 Footer Athletic Socks, White, One Size | D2: WIGF1019_051_wht_0 | E2: 86 | F2: 2 | G2: 0.0001 | H2: 0.0001 | I2: 123 | J2: 2 | K2: 0.0001 | L2: 0.0001 | M2: 0.1339 | N2: 0 | O2: 5 | P2: 0 | Q2: 0.0581 | R2: 0 | S2: 74.95 | T2: 0 | U2: 3 | V2: 0 | AA2: WIGF1019_051_wht_0 | AB2: 5 | AC2: WIGF1019_051_wht_0 | AD2: 74.95 | AE2: WIGF1019_051_wht_0 | AF2: 86 | AG2: WIGF1019_051_wht_0 | AH2: 0.1339
A3: B00NF6Y9LW | B3: B0019OTSH2 | C3: WigWam Volley Athletic Socks, White, Md | D3: WIGF1054_051_whi_1 | E3: 7 | F3: 0 | G3: 0 | H3: 0 | I3: 11 | J3: 0 | K3: 0 | L3: 0 | M3: 1 | N3: 0 | O3: 5 | P3: 0 | Q3: 0.7143 | R3: 0 | S3: 65 | T3: 0 | U3: 2 | V3: 0 | AA3: WIGF1054_051_whi_1 | AB3: 5 | AC3: WIGF1054_051_whi_1 | AD3: 65 | AE3: WIGF1054_051_whi_1 | AF3: 7 | AG3: WIGF1054_051_whi_1 | AH3: 1
A4: B00NF6Y9LW | B4: B000G7Y0AS | C4: WigWam Volley Athletic Socks, Black, Lg | D4: WIGF1054_052_bla_2 | E4: 11 | F4: 0 | G4: 0 | H4: 0 | I4: 17 | J4: 0 | K4: 0 | L4: 0 | M4: 1 | N4: 0 | O4: 3 | P4: 0 | Q4: 0.2727 | R4: 0 | S4: 39 | T4: 0 | U4: 2 | V4: 0 | AA4: WIGF1054_052_bla_2 | AB4: 3 | AC4: WIGF1054_052_bla_2 | AD4: 39 | AE4: WIGF1054_052_bla_2 | AF4: 11 | AG4: WIGF1054_052_bla_2 | AH4: 1
A5: B00NF6Y9LW | B5: B000V5EE56 | C5: WigWam Volley Athletic Socks, Black, Xl | D5: WIGF1054_052_bla_3 | E5: 2 | F5: 0 | G5: 0 | H5: 0 | I5: 7 | J5: 0 | K5: 0 | L5: 0 | M5: 1 | N5: 0 | O5: 1 | P5: 0 | Q5: 0.5 | R5: 0 | S5: 13 | T5: 0 | U5: 1 | V5: 0 | AA5: WIGF1054_052_bla_3 | AB5: 1 | AC5: WIGF1054_052_bla_3 | AD5: 13 | AE5: WIGF1054_052_bla_3 | AF5: 2 | AG5: WIGF1054_052_bla_3 | AH5: 1
A6: B000TF9LZG | B6: B000TA744G | C6: Wigwam King Cotton Crew F1055 Sock | D6: WIGF1055_051_wht_1 | E6: 271 | F6: 4 | G6: 0.0002 | H6: 0.0002 | I6: 390 | J6: 4 | K6: 0.0002 | L6: 0.0001 | M6: 1 | N6: 1 | O6: 87 | P6: 0 | Q6: 0.321 | R6: 0 | S6: 1304.13 | T6: 0 | U6: 34 | V6: 0 | AA6: WIGF1055_051_wht_1 | AB6: 87 | AC6: WIGF1055_051_wht_1 | AD6: 1304.13 | AE6: WIGF1055_051_wht_1 | AF6: 271 | AG6: WIGF1055_051_wht_1 | AH6: 1
A7: B000TF9LZG | B7: B000TA1SJI | C7: Wigwam King Cotton Heavyweight Crew Socks, White - X-Large | D7: WIGF1055_051_wht_2 | E7: 131 | F7: 1 | G7: 0.0001 | H7: 0 | I7: 177 | J7: 1 | K7: 0.0001 | L7: 0 | M7: 1 | N7: 1 | O7: 46 | P7: 0 | Q7: 0.3511 | R7: 0 | S7: 690 | T7: 0 | U7: 19 | V7: 0 | AA7: WIGF1055_051_wht_2 | AB7: 46 | AC7: WIGF1055_051_wht_2 | AD7: 690 | AE7: WIGF1055_051_wht_2 | AF7: 131 | AG7: WIGF1055_051_wht_2 | AH7: 1
A8: B000TF9LZG | B8: B004QJOC00 | C8: WigWam Men's King Crew Athletic Socks, X-Large Sock , Black | D8: WIGF1055_052_blk_2 | E8: 36 | F8: 0 | G8: 0 | H8: 0 | I8: 52 | J8: 0 | K8: 0 | L8: 0 | M8: 0.4894 | N8: 0 | O8: 7 | P8: 0 | Q8: 0.1944 | R8: 0 | S8: 105 | T8: 0 | U8: 5 | V8: 0 | AA8: WIGF1055_052_blk_2 | AB8: 7 | AC8: WIGF1055_052_blk_2 | AD8: 105 | AE8: WIGF1055_052_blk_2 | AF8: 36 | AG8: WIGF1055_052_blk_2 | AH8: 0.4894
A9: B00NF6Y5N4 | B9: B0088V4SG0 | C9: Wigwam Master F1061 Sock, White - 13 | D9: WIGF1061_051_wht_3 | E9: 20 | F9: 0 | G9: 0 | H9: 0 | I9: 36 | J9: 0 | K9: 0 | L9: 0 | M9: 0.9688 | N9: 0 | O9: 8 | P9: 0 | Q9: 0.4 | R9: 0 | S9: 144 | T9: 0 | U9: 3 | V9: 0 | AA9: WIGF1061_051_wht_3 | AB9: 8 | AC9: WIGF1061_051_wht_3 | AD9: 144 | AE9: WIGF1061_051_wht_3 | AF9: 20 | AG9: WIGF1061_051_wht_3 | AH9: 0.9688
A10: B00NF6XO9A | B10: B000AREBGM | C10: Wigwam Men's Advantage Socks, White, X-Large | D10: WIGF1072_051_wht_2 | E10: 84 | F10: 0 | G10: 0.0001 | H10: 0 | I10: 105 | J10: 0 | K10: 0.0001 | L10: 0 | M10: 0.9902 | N10: 0 | O10: 2 | P10: 0 | Q10: 0.0238 | R10: 0 | S10: 28 | T10: 0 | U10: 2 | V10: 0 | AA10: WIGF1072_051_wht_2 | AB10: 2 | AC10: WIGF1072_051_wht_2 | AD10: 28 | AE10: WIGF1072_051_wht_2 | AF10: 84 | AG10: WIGF1072_051_wht_2 | AH10: 0.9902
A11: B0CL7S1PQQ | B11: B000ARG1KG | C11: Wigwam 625 Light Weight Wool Athletic Socks, White, X-Large | D11: WIGF1086_051_nat_2 | E11: 191 | F11: 2 | G11: 0.0001 | H11: 0.0001 | I11: 298 | J11: 3 | K11: 0.0001 | L11: 0.0001 | M11: 0.3222 | N11: 0 | O11: 4 | P11: 0 | Q11: 0.0209 | R11: 0 | S11: 87.96 | T11: 0 | U11: 3 | V11: 0 | AA11: WIGF1086_051_nat_2 | AB11: 4 | AC11: WIGF1086_051_nat_2 | AD11: 87.96 | AE11: WIGF1086_051_nat_2 | AF11: 191 | AG11: WIGF1086_051_nat_2 | AH11: 0.3222
A12: B07CPGJV5L | B12: B000FCILZE | C12: Wigwam At Work Steel Toe Crew Socks, White/Black - Medium | D12: WIGF1140_731_whi_1 | E12: 16 | F12: 1 | G12: 0 | H12: 0 | I12: 19 | J12: 1 | K12: 0 | L12: 0 | M12: 1 | N12: 0 | O12: 8 | P12: 0 | Q12: 0.5 | R12: 0 | S12: 128 | T12: 0 | U12: 3 | V12: 0 | AA12: WIGF1140_731_whi_1 | AB12: 8 | AC12: WIGF1140_731_whi_1 | AD12: 128 | AE12: WIGF1140_731_whi_1 | AF12: 16 | AG12: WIGF1140_731_whi_1 | AH12: 1
A13: B09C6RG3TW | B13: B000KPHTWW | C13: Wigwam Men's Diabetic Walker Crew Length Sock,White,XL/shoe Size: Men's 12-15 | D13: WIGF1221_051_wht_2 | E13: 18 | F13: 0 | G13: 0 | H13: 0 | I13: 34 | J13: 0 | K13: 0 | L13: 0 | M13: 1 | N13: 0 | O13: 5 | P13: 0 | Q13: 0.2778 | R13: 0 | S13: 70 | T13: 0 | U13: 2 | V13: 0 | AA13: WIGF1221_051_wht_2 | AB13: 5 | AC13: WIGF1221_051_wht_2 | AD13: 70 | AE13: WIGF1221_051_wht_2 | AF13: 18 | AG13: WIGF1221_051_wht_2 | AH13: 1
... A234: B0GKX2WQVX | B234: B008PJBOW6 | C234: Wigwam Super 60 Crew 6 Pack S9020 Sock, White - XL | D234: ZZWIGS9020_51_whi_3 | E234: 75 | F234: 1 | G234: 0 | H234: 0 | I234: 104 | J234: 1 | K234: 0 | L234: 0 | M234: 0.6939 | N234: 0 | O234: 5 | P234: 0 | Q234: 0.0667 | R234: 0 | S234: 169.95 | T234: 0 | U234: 5 | V234: 0 | AA234: ZZWIGS9020_51_whi_3 | AB234: 5 | AC234: ZZWIGS9020_51_whi_3 | AD234: 169.95 | AE234: ZZWIGS9020_51_whi_3 | AF234: 75 | AG234: ZZWIGS9020_51_whi_3 | AH234: 0.6939
